Workbook

Sheet Assumptions
A1: Z-GATE LTD — Financial Model Assumptions (90-Day Detail + 12-Month Outlook)
A2: Edit the blue text / yellow-filled cells to update the model. All other cells are formulas and will recalculate automatically.
A4: LEGEND
A5: Blue text, yellow fill | B5: Editable input — change this to update the model
A6: Black text | B6: Formula — do not overwrite
A7: Green text | B7: Link pulled from another sheet
A8: TABLE A — UNIT ECONOMICS (single values, RWF unless noted)
A9: Driver | B9: Value | E9: Notes / Source
A10: Opening cash (share capital) | B10: 5000000 | E10: Source: RDB registration certificate — 100 ordinary shares × RWF 50,000
A11: Advisory — monthly retainer fee per client (RWF) | B11: 150000 | E11: Planning estimate — mid-market SME compliance package
A12: Academy — course fee per learner (RWF) | B12: 40000 | E12: Planning estimate — short-course pricing
A13: Data — monthly fee per client (RWF) | B13: 300000 | E13: Planning estimate — SME reporting/BI retainer
A14: Contingency reserve — total held across 90 days (RWF) | B14: 500000 | E14: Held reserve; drawn only if needed (see Cash Flow sheet)
A16: TABLE B — MONTHLY VOLUME & COST DRIVERS (RWF unless noted)
A17: Driver | B17: Month 1 | C17: Month 2 | D17: Month 3 | E17: Notes
A18: VOLUME
A19: Advisory — active retainer clients | B19: 3 | C19: 7 | D19: 10 | E19: From 90-Day Roadmap (Nyarugenge CBD launch → Gasabo expansion)
A20: Academy — learners enrolled | B20: 0 | C20: 18 | D20: 15 | E20: First cohort Month 2, second cohort Month 3
A21: Data — active clients | B21: 0 | C21: 0 | D21: 1 | E21: First external client onboarded Month 3
A22: Tech — external revenue (direct RWF override) | B22: 0 | C22: 0 | D22: 0 | E22: Internal builds only in first 90 days; no external revenue yet
A23: STAFFING (RWF/month)
A24: Advisory associate / bookkeeper | B24: 250000 | C24: 250000 | D24: 250000 | E24: Hired Month 1
A25: Marketing coordinator (part-time) | B25: 150000 | C25: 150000 | D25: 150000 | E25: Hired Month 1
A26: Academy trainer (contract, per cohort) | B26: 0 | C26: 200000 | D26: 200000 | E26: Paid in months with an active cohort
A27: Junior developer (contract) | B27: 0 | C27: 0 | D27: 300000 | E27: Hired Month 3
A28: Data analyst (contract) | B28: 0 | C28: 0 | D28: 300000 | E28: Hired Month 3
A29: OPERATING (RWF/month)
A30: Marketing & brand launch | B30: 500000 | C30: 400000 | D30: 350000 | E30: Heaviest in launch month
A31: Tools & software (accounting, EBM system, LMS, hosting) | B31: 350000 | C31: 350000 | D31: 300000
A32: Legal, compliance & activity-code review | B32: 350000 | C32: 150000 | D32: 0 | E32: Front-loaded — RDB activity code review, contracts
A34: TABLE C — QUARTERLY VOLUME & COST DRIVERS, MONTHS 4-12 (RWF unless noted)
A35: Driver | B35: Q2 (Mo 4-6) | C35: Q3 (Mo 7-9) | D35: Q4 (Mo 10-12) | E35: Notes
A36: VOLUME
A37: Advisory — active retainer clients (quarter avg) | B37: 14 | C37: 20 | D37: 26 | E37: Continued growth from 10 clients at Day 90
A38: Academy — learners enrolled (quarter total) | B38: 18 | C38: 18 | D38: 36 | E38: 1 cohort/quarter in Q2-Q3, 2 cohorts in Q4
A39: Data — active clients (quarter avg) | B39: 2 | C39: 3 | D39: 4 | E39: Steady client-base growth
A40: Tech — external revenue (quarter total, direct RWF override) | B40: 1200000 | C40: 1800000 | D40: 2400000 | E40: External Tech client revenue begins Month 4
A41: COSTS (quarter total, RWF)
A42: Staffing (quarter total) | B42: 3600000 | C42: 3600000 | D42: 4200000 | E42: Q4 adds a second Advisory associate as client base grows
A43: Marketing (quarter total) | B43: 750000 | C43: 750000 | D43: 750000 | E43: Tapers to steady-state run-rate after launch quarter
...

Sheet Revenue & Cost Model
A1: Revenue & Cost Build-Up
A2: All figures in RWF. Pulled from Assumptions — do not overwrite formula cells (black text).
A4: Line Item | B4: Month 1 | C4: Month 2 | D4: Month 3 | E4: 90-Day Total
A5: REVENUE BY DIVISION
A6: Advisory — retainer revenue | B6: =Assumptions!$B$19*Assumptions!$B$11 -> 450000 | C6: =Assumptions!$C$19*Assumptions!$B$11 -> 1050000 | D6: =Assumptions!$D$19*Assumptions!$B$11 -> 1500000 | E6: =SUM(B6:D6) -> 3000000
A7: Academy — course revenue | B7: =Assumptions!$B$20*Assumptions!$B$12 -> 0 | C7: =Assumptions!$C$20*Assumptions!$B$12 -> 720000 | D7: =Assumptions!$D$20*Assumptions!$B$12 -> 600000 | E7: =SUM(B7:D7) -> 1320000
A8: Tech — external revenue | B8: =Assumptions!$B$22 -> 0 | C8: =Assumptions!$C$22 -> 0 | D8: =Assumptions!$D$22 -> 0 | E8: =SUM(B8:D8) -> 0
A9: Data — retainer revenue | B9: =Assumptions!$B$21*Assumptions!$B$13 -> 0 | C9: =Assumptions!$C$21*Assumptions!$B$13 -> 0 | D9: =Assumptions!$D$21*Assumptions!$B$13 -> 300000 | E9: =SUM(B9:D9) -> 300000
A10: TOTAL REVENUE | B10: =SUM(B6:B9) -> 450000 | C10: =SUM(C6:C9) -> 1770000 | D10: =SUM(D6:D9) -> 2400000 | E10: =SUM(E6:E9) -> 4620000
A12: COSTS
A13: Advisory associate / bookkeeper | B13: =Assumptions!$B$24 -> 250000 | C13: =Assumptions!$C$24 -> 250000 | D13: =Assumptions!$D$24 -> 250000 | E13: =SUM(B13:D13) -> 750000
A14: Marketing coordinator (part-time) | B14: =Assumptions!$B$25 -> 150000 | C14: =Assumptions!$C$25 -> 150000 | D14: =Assumptions!$D$25 -> 150000 | E14: =SUM(B14:D14) -> 450000
A15: Academy trainer (contract, per cohort) | B15: =Assumptions!$B$26 -> 0 | C15: =Assumptions!$C$26 -> 200000 | D15: =Assumptions!$D$26 -> 200000 | E15: =SUM(B15:D15) -> 400000
A16: Junior developer (contract) | B16: =Assumptions!$B$27 -> 0 | C16: =Assumptions!$C$27 -> 0 | D16: =Assumptions!$D$27 -> 300000 | E16: =SUM(B16:D16) -> 300000
A17: Data analyst (contract) | B17: =Assumptions!$B$28 -> 0 | C17: =Assumptions!$C$28 -> 0 | D17: =Assumptions!$D$28 -> 300000 | E17: =SUM(B17:D17) -> 300000
A18: Marketing & brand launch | B18: =Assumptions!$B$30 -> 500000 | C18: =Assumptions!$C$30 -> 400000 | D18: =Assumptions!$D$30 -> 350000 | E18: =SUM(B18:D18) -> 1250000
A19: Tools & software (accounting, EBM system, LMS, hosting) | B19: =Assumptions!$B$31 -> 350000 | C19: =Assumptions!$C$31 -> 350000 | D19: =Assumptions!$D$31 -> 300000 | E19: =SUM(B19:D19) -> 1000000
A20: Legal, compliance & activity-code review | B20: =Assumptions!$B$32 -> 350000 | C20: =Assumptions!$C$32 -> 150000 | D20: =Assumptions!$D$32 -> 0 | E20: =SUM(B20:D20) -> 500000
A21: TOTAL COSTS | B21: =SUM(B13:B20) -> 1600000 | C21: =SUM(C13:C20) -> 1500000 | D21: =SUM(D13:D20) -> 1850000 | E21: =SUM(E13:E20) -> 4950000
A23: NET OPERATING RESULT (Revenue − Costs) | B23: =B10-B21 -> -1150000 | C23: =C10-C21 -> 270000 | D23: =D10-D21 -> 550000 | E23: =E10-E21 -> -330000

Sheet Cash Flow
A1: 90-Day Cash Flow Statement
A2: All figures in RWF. Links to Revenue & Cost Model and Assumptions (green text) — do not overwrite.
A4: Line Item | B4: Month 1 | C4: Month 2 | D4: Month 3 | E4: 90-Day Total
A5: Opening Cash Balance | B5: =Assumptions!$B$10 -> 5000000
A6: (+) Total Revenue | B6: ='Revenue & Cost Model'!B10 -> 450000 | C6: ='Revenue & Cost Model'!C10 -> 1770000 | D6: ='Revenue & Cost Model'!D10 -> 2400000 | E6: ='Revenue & Cost Model'!E10 -> 4620000
A7: (−) Total Costs | B7: ='Revenue & Cost Model'!B21 -> 1600000 | C7: ='Revenue & Cost Model'!C21 -> 1500000 | D7: ='Revenue & Cost Model'!D21 -> 1850000 | E7: ='Revenue & Cost Model'!E21 -> 4950000
A8: Net Cash Flow | B8: =B6-B7 -> -1150000 | C8: =C6-C7 -> 270000 | D8: =D6-D7 -> 550000 | E8: =SUM(B8:D8) -> -330000
A9: Closing Cash Balance | B9: =B5+B8 -> 3850000 | C9: =B9+C8 -> 4120000 | D9: =C9+D8 -> 4670000 | E9: =D9 -> 4670000
A12: CONTINGENCY & HEADROOM
A13: Contingency reserve held (not drawn above) | B13: =Assumptions!$B$14 -> 500000 | C13: Held in reserve across the 90 days; draw down manually only if a risk in the Business Plan's risk register materializes.
A14: Closing cash as % of starting capital | B14: =D9/B5 -> 0.934

Sheet 12-Month Cash Flow
A1: 12-Month Cash Flow Outlook
A2: Months 1-3 (green) link to the Cash Flow sheet's detailed build. Q2-Q4 (green) are computed from Assumptions Table C. Edit Table C to update the outlook.
A4: Line Item | B4: Month 1 | C4: Month 2 | D4: Month 3 | E4: Q2 (Mo 4-6) | F4: Q3 (Mo 7-9) | G4: Q4 (Mo 10-12) | H4: 12-Month Total
A5: Total Revenue | B5: ='Revenue & Cost Model'!B10 -> 450000 | C5: ='Revenue & Cost Model'!C10 -> 1770000 | D5: ='Revenue & Cost Model'!D10 -> 2400000 | E5: =Assumptions!$B$37*Assumptions!$B$11*3+Assumptions!$B$38*Assumptions!$B$12+Assumptions!$B$39*Assumptions!$B$13*3+Assumptions!$B$40 -> 10020000 | F5: =Assumptions!$C$37*Assumptions!$B$11*3+Assumptions!$C$38*Assumptions!$B$12+Assumptions!$C$39*Assumptions!$B$13*3+Assumptions!$C$40 -> 14220000 | G5: =Assumptions!$D$37*Assumptions!$B$11*3+Assumptions!$D$38*Assumptions!$B$12+Assumptions!$D$39*Assumptions!$B$13*3+Assumptions!$D$40 -> 19140000 | H5: =SUM(B5:G5) -> 48000000
A6: Total Costs | B6: ='Revenue & Cost Model'!B21 -> 1600000 | C6: ='Revenue & Cost Model'!C21 -> 1500000 | D6: ='Revenue & Cost Model'!D21 -> 1850000 | E6: =Assumptions!$B$42+Assumptions!$B$43+Assumptions!$B$44+Assumptions!$B$45 -> 5400000 | F6: =Assumptions!$C$42+Assumptions!$C$43+Assumptions!$C$44+Assumptions!$C$45 -> 5400000 | G6: =Assumptions!$D$42+Assumptions!$D$43+Assumptions!$D$44+Assumptions!$D$45 -> 6000000 | H6: =SUM(B6:G6) -> 21750000
A7: Net Cash Flow | B7: =B5-B6 -> -1150000 | C7: =C5-C6 -> 270000 | D7: =D5-D6 -> 550000 | E7: =E5-E6 -> 4620000 | F7: =F5-F6 -> 8820000 | G7: =G5-G6 -> 13140000 | H7: =SUM(B7:G7) -> 26250000
A8: Closing Cash Balance | B8: =Assumptions!$B$10+B7 -> 3850000 | C8: =B8+C7 -> 4120000 | D8: =C8+D7 -> 4670000 | E8: =D8+E7 -> 9290000 | F8: =E8+F7 -> 18110000 | G8: =F8+G7 -> 31250000 | H8: =G8 -> 31250000
A10: Closing cash as % of starting capital (Month 12) | B10: =G8/Assumptions!$B$10 -> 6.25
A11: Revenue growth, Month-1 run-rate vs Q4 monthly average | B11: =(G5/3)/B5 -> 14.177778

Sheet Summary Dashboard
A1: Z-GATE LTD — Financial Summary (90-Day Detail + 12-Month Outlook)
A2: Rows 1-4 pulled from Cash Flow and Revenue & Cost Model sheets (90-day detail). The 12-Month Outlook table below pulls from the 12-Month Cash Flow sheet.
A4: Metric | B4: Month 1 | C4: Month 2 | D4: Month 3 | E4: 90-Day Total
A5: Total Revenue (RWF) | B5: ='Revenue & Cost Model'!B10 -> 450000 | C5: ='Revenue & Cost Model'!C10 -> 1770000 | D5: ='Revenue & Cost Model'!D10 -> 2400000 | E5: ='Revenue & Cost Model'!E10 -> 4620000
A6: Total Costs (RWF) | B6: ='Revenue & Cost Model'!B21 -> 1600000 | C6: ='Revenue & Cost Model'!C21 -> 1500000 | D6: ='Revenue & Cost Model'!D21 -> 1850000 | E6: ='Revenue & Cost Model'!E21 -> 4950000
A7: Net Cash Flow (RWF) | B7: ='Cash Flow'!B8 -> -1150000 | C7: ='Cash Flow'!C8 -> 270000 | D7: ='Cash Flow'!D8 -> 550000 | E7: ='Cash Flow'!E8 -> -330000
A8: Closing Cash Balance (RWF) | B8: ='Cash Flow'!B9 -> 3850000 | C8: ='Cash Flow'!C9 -> 4120000 | D8: ='Cash Flow'!D9 -> 4670000 | E8: ='Cash Flow'!E9 -> 4670000
A10: KEY TAKEAWAYS
A11: • Revenue accelerates every month as Advisory retainers grow (3 → 7 → 10 clients) and Academy's first two cohorts land in Months 2–3.
A12: • Costs are heaviest in Month 1 (launch/legal/marketing) and shift toward staffing as Tech and Data hires start in Month 3.
A13: • The model projects a modest net use of cash over 90 days, ending with the large majority of starting capital retained — consistent with an intentional launch-quarter investment, not a shortfall.
A14: • The RWF 500,000 contingency reserve is held untouched in this base case; treat it as insurance against the risks named in the Business Plan's risk register, not as spendable budget.
A15: • Beyond Day 90, the 12-Month Outlook (Assumptions Table C) projects continued Advisory client growth (10 → 26), a second Advisory hire in Q4, and Tech external revenue ramping from RWF 1.2M to RWF 2.4M per quarter — treat Q2-Q4 as directional planning figures, not a committed forecast.
A17: 12-MONTH OUTLOOK
A18: Metric | B18: Q1 (Mo 1-3) | C18: Q2 (Mo 4-6) | D18: Q3 (Mo 7-9) | E18: Q4 (Mo 10-12)
A19: Revenue (RWF) | B19: =SUM('12-Month Cash Flow'!B5:D5) -> 4620000 | C19: ='12-Month Cash Flow'!E5 -> 10020000 | D19: ='12-Month Cash Flow'!F5 -> 14220000 | E19: ='12-Month Cash Flow'!G5 -> 19140000
A20: Costs (RWF) | B20: =SUM('12-Month Cash Flow'!B6:D6) -> 4950000 | C20: ='12-Month Cash Flow'!E6 -> 5400000 | D20: ='12-Month Cash Flow'!F6 -> 5400000 | E20: ='12-Month Cash Flow'!G6 -> 6000000
A21: Net Cash Flow (RWF) | B21: =SUM('12-Month Cash Flow'!B7:D7) -> -330000 | C21: ='12-Month Cash Flow'!E7 -> 4620000 | D21: ='12-Month Cash Flow'!F7 -> 8820000 | E21: ='12-Month Cash Flow'!G7 -> 13140000
A22: Closing Cash Balance (RWF) | B22: ='Cash Flow'!D9 -> 4670000 | C22: ='12-Month Cash Flow'!E8 -> 9290000 | D22: ='12-Month Cash Flow'!F8 -> 18110000 | E22: ='12-Month Cash Flow'!G8 -> 31250000
A24: Chart Data | B24: Revenue | C24: Costs
A25: Month 1 | B25: ='Revenue & Cost Model'!B10 -> 450000 | C25: ='Revenue & Cost Model'!B21 -> 1600000
A26: Month 2 | B26: ='Revenue & Cost Model'!C10 -> 1770000 | C26: ='Revenue & Cost Model'!C21 -> 1500000
A27: Month 3 | B27: ='Revenue & Cost Model'!D10 -> 2400000 | C27: ='Revenue & Cost Model'!D21 -> 1850000
A46: Chart Data (12-Month) | B46: Revenue | C46: Costs
A47: Q1 (Mo 1-3) | B47: =SUM('12-Month Cash Flow'!B5:D5) -> 4620000 | C47: =SUM('12-Month Cash Flow'!B6:D6) -> 4950000
A48: Q2 (Mo 4-6) | B48: ='12-Month Cash Flow'!E5 -> 10020000 | C48: ='12-Month Cash Flow'!E6 -> 5400000
A49: Q3 (Mo 7-9) | B49: ='12-Month Cash Flow'!F5 -> 14220000 | C49: ='12-Month Cash Flow'!F6 -> 5400000
A50: Q4 (Mo 10-12) | B50: ='12-Month Cash Flow'!G5 -> 19140000 | C50: ='12-Month Cash Flow'!G6 -> 6000000
